Workbook

Sheet SUMMARY
A2: JINA | B2: KIINGILIO | C2: HISA | D2: MICHANGO MBALIMBALI | E2: RIBA | G2: FAINI | H2: JUMLA KUU
A3: ALMA MOLLEL | B3: 0 | C3: =HISA!P5 -> 900000 | D3: =JAMII!P4 -> 90000 | E3: 1650000 | G3: =FAINI!O3 -> 2000 | H3: =SUM(C3:G3) -> 2642000
A4: BEATRICE MESULI | B4: 0 | C4: =HISA!P6 -> 500000 | D4: =JAMII!P5 -> 75000 | G4: =FAINI!O4 -> 105000 | H4: =SUM(C4:G4) -> 680000
A5: CATHERINE EDWARD | B5: 0 | C5: =HISA!P7 -> 1400000 | D5: =JAMII!P6 -> 90000 | G5: =FAINI!O5 -> 19000 | H5: =SUM(C5:G5) -> 1509000
A6: CHRISTINA TAIRO | B6: 0 | C6: =HISA!P8 -> 2800000 | D6: =JAMII!P7 -> 90000 | E6: 2000000 | G6: =FAINI!O6 -> 14000 | H6: =SUM(C6:G6) -> 4904000
A7: ELIZABETH MOREHE | B7: 0 | C7: =HISA!P9 -> 3800000 | D7: =JAMII!P8 -> 90000 | G7: =FAINI!O7 -> 4000 | H7: =SUM(C7:G7) -> 3894000
A8: JANETH MKWIZU | B8: 0 | C8: =HISA!P10 -> 2000000 | D8: =JAMII!P9 -> 30000 | G8: =FAINI!O8 -> 302000 | H8: =SUM(C8:G8) -> 2332000
A9: KEMILEMBE MUGELE | B9: 0 | C9: =HISA!P11 -> 1100000 | D9: =JAMII!P10 -> 90000 | G9: =FAINI!O9 -> 14000 | H9: =SUM(C9:G9) -> 1204000
A10: MALIKA MANG'ERA | B10: 0 | C10: =HISA!P12 -> 2500000 | D10: =JAMII!P11 -> 75000 | E10: 2200000 | G10: =FAINI!O10 -> 137000 | H10: =SUM(C10:G10) -> 4912000
A11: MARY KAPOSWE | B11: 0 | C11: =HISA!P13 -> 500000 | D11: =JAMII!P12 -> 60000 | G11: =FAINI!O11 -> 159000 | H11: =SUM(C11:G11) -> 719000
A12: EMILY EDWARD | B12: 0 | C12: =HISA!P14 -> 500000 | D12: =JAMII!P13 -> 75000 | E12: 1300000 | G12: =FAINI!O12 -> 174000 | H12: =SUM(C12:G12) -> 2049000
A13: RAMONA GILBERT | B13: 0 | C13: =HISA!P15 -> 600000 | D13: =JAMII!P14 -> 75000 | G13: =FAINI!O13 -> 0 | H13: =SUM(C13:G13) -> 675000
A14: REGINA CHARLES | B14: 0 | C14: =HISA!P16 -> 11000000 | D14: =JAMII!P15 -> 75000 | G14: =FAINI!O14 -> 4000 | H14: =SUM(C14:G14) -> 11079000
A15: ROSEMARY LAIZER | B15: 0 | C15: =HISA!P17 -> 800000 | D15: =JAMII!P16 -> 60000 | G15: =FAINI!O15 -> 153000 | H15: =SUM(C15:G15) -> 1013000
A16: RUQAIYA JAWADI | B16: 0 | C16: =HISA!P18 -> 6000000 | D16: =JAMII!P17 -> 90000 | G16: =FAINI!O16 -> 174000 | H16: =SUM(C16:G16) -> 6264000
A17: SCHOLASTICA KIVUYO | B17: 0 | C17: =HISA!P19 -> 800000 | D17: =JAMII!P18 -> 75000 | G17: =FAINI!O17 -> 158000 | H17: =SUM(C17:G17) -> 1033000
A18: HILDA MESULI | B18: 0 | C18: =HISA!P20 -> 600000 | D18: =JAMII!P19 -> 90000 | G18: =FAINI!O18 -> 205000 | H18: =SUM(C18:G18) -> 895000
A19: PATRICIA MGISHA | B19: 0 | C19: =HISA!P21 -> 700000 | D19: =JAMII!P20 -> 90000 | E19: 300000 | G19: =FAINI!O19 -> 143000 | H19: =SUM(C19:G19) -> 1233000
A20: UPENDO MMARY | B20: 0 | C20: =HISA!P22 -> 2100000 | D20: =JAMII!P21 -> 90000 | G20: =FAINI!O20 -> 139000 | H20: =SUM(C20:G20) -> 2329000
B21: =SUM(B3:B20) -> 0 | C21: =SUM(C3:C20) -> 38600000 | D21: =SUM(D3:D20) -> 1410000 | E21: =SUM(E3:E20) -> 7450000 | F21: =SUM(F3:F20) -> 0 | G21: =SUM(G3:G20) -> 1906000 | H21: =SUM(H3:H20) -> 49366000
A23: JUMLA YA MAPATO YA KIKUNDI | E23: =SUM(E3:E20) -> 7450000
C24: MAKATO BANK
C25: UCHAKAVU BALANCE
B27: HISA ZA MWANACHAMA KWA MWAKA | C27: GAWIO LA FAIDA YA RIBA (Hisa za mwanachama/jumla ya hisa zote*jumla ya riba iliyokusanywa | D27: GAWIO KUTOKANA NA UCHAKAVU BAADA YA MATUMIZI | E27: GAWIO KUTOKANA NA FAINI | F27: PUNGUZO LA MADENI YA MWANACHAMA | G27: GAWIO HALISI LA MWANACHAMA KWA MWAKA 2024
A28: JINA | D28: =D25/18 -> 0 | E28: =G21/18 -> 105888.89
A29: ALMA MOLLEL | B29: =C3 -> 900000 | C29: =B29/B47*E23 -> 173704.66 | E29: 105888.89 | G29: =B29+C29+D29+E29-F29 -> 1179593.6
A30: BEATRICE MESULI | B30: =C4 -> 500000 | C30: =B30/B47*E23 -> 96502.591 | E30: 105888.89 | G30: =B30+C30+D30+E30-F30 -> 702391.48
A31: CATHERINE EDWARD | B31: =C5 -> 1400000 | C31: =B31/B47*E23 -> 270207.25 | E31: 105888.89 | G31: =B31+C31+D31+E31-F31 -> 1776096.1
A32: CHRISTINA TAIRO | B32: =C6 -> 2800000 | C32: =B32/B47*E23 -> 540414.51 | E32: 105888.89 | G32: =B32+C32+D32+E32-F32 -> 3446303.4
A33: ELIZABETH MOREHE | B33: =C7 -> 3800000 | C33: =B33/B47*E23 -> 733419.69 | E33: 105888.89 | G33: =B33+C33+D33+E33-F33 -> 4639308.6
A34: JANETH MKWIZU | B34: =C8 -> 2000000 | C34: =B34/B47*E23 -> 386010.36 | E34: 105888.89 | G34: =B34+C34+D34+E34-F34 -> 2491899.3
A35: KEMILEMBE MUGELE | B35: =C9 -> 1100000 | C35: =B35/B47*E23 -> 212305.7 | E35: 105888.89 | G35: =B35+C35+D35+E35-F35 -> 1418194.6
A36: MALIKA MANG'ERA | B36: =C10 -> 2500000 | C36: =B36/B47*E23 -> 482512.95 | E36: 105888.89 | G36: =B36+C36+D36+E36-F36 -> 3088401.8
A37: MARY KAPOSWE | B37: =C11 -> 500000 | C37: =B37/B47*E23 -> 96502.591 | E37: 105888.89 | G37: =B37+C37+D37+E37-F37 -> 702391.48
A38: EMILY EDWARD | B38: =C12 -> 500000 | C38: =B38/B47*E23 -> 96502.591 | E38: 105888.89 | G38: =B38+C38+D38+E38-F38 -> 702391.48
A39: RAMONA GILBERT | B39: =C13 -> 600000 | C39: =B39/B47*E23 -> 115803.11 | E39: 105888.89 | G39: =B39+C39+D39+E39-F39 -> 821692
A40: REGINA CHARLES | B40: =C14 -> 11000000 | C40: =B40/B47*E23 -> 2123057 | E40: 105888.89 | G40: =B40+C40+D40+E40-F40 -> 13228946
A41: ROSEMARY LAIZER | B41: =C15 -> 800000 | C41: =B41/B47*E23 -> 154404.15 | E41: 105888.89 | G41: =B41+C41+D41+E41-F41 -> 1060293
A42: RUQAIYA JAWADI | B42: =C16 -> 6000000 | C42: =B42/B47*E23 -> 1158031.1 | E42: 105888.89 | G42: =B42+C42+D42+E42-F42 -> 7263920
A43: SCHOLASTICA KIVUYO | B43: =C17 -> 800000 | C43: =B43/B47*E23 -> 154404.15 | E43: 105888.89 | G43: =B43+C43+D43+E43-F43 -> 1060293
...

Sheet HISA
E2: HISA ZA WANAKIKUNDI WA DIVAS VICOBA | L2: HISA ZA WANAKIKUNDI WA DIVAS VICOBA
A3: @ | B3: 100000
A4: S/N | B4: JINA | C4: 45627 | D4: 45658 | E4: 45689 | F4: 45717 | G4: 45748 | H4: 45778 | I4: 45809 | J4: 45839 | K4: 45870 | L4: 45901 | M4: 45931 | N4: 45962 | O4: 45992 | P4: JUMLA YA HISA | Q4: IDADI YA HISA | R4: HISA NYONGEZA
A5: 1 | B5: ALMA MOLLEL | C5: 100000 | D5: 100000 | E5: 200000 | F5: 100000 | G5: 200000 | H5: 200000 | P5: =SUM(C5:O5) -> 900000 | Q5: =P5/100000 -> 9
A6: 2 | B6: BEATRICE MESULI | C6: 100000 | D6: 100000 | E6: 100000 | F6: 100000 | G6: 100000 | H6: 0 | P6: =SUM(C6:O6) -> 500000 | Q6: =P6/100000 -> 5
A7: 3 | B7: CATHERINE EDWARD | C7: 300000 | D7: 300000 | E7: 200000 | F7: 200000 | G7: 300000 | H7: 100000 | P7: =SUM(C7:O7) -> 1400000 | Q7: =P7/100000 -> 14
A8: 4 | B8: CHRISTINA TAIRO | C8: 300000 | D8: 500000 | E8: 500000 | F8: 500000 | G8: 500000 | H8: 500000 | P8: =SUM(C8:O8) -> 2800000 | Q8: =P8/100000 -> 28
A9: 5 | B9: ELIZABETH MOREHE | C9: 1000000 | D9: 500000 | E9: 600000 | F9: 600000 | G9: 600000 | H9: 500000 | P9: =SUM(C9:O9) -> 3800000 | Q9: =P9/100000 -> 38
A10: 6 | B10: JANETH MKWIZU | C10: 1000000 | D10: 1000000 | E10: 0 | F10: 0 | G10: 0 | H10: 0 | P10: =SUM(C10:O10) -> 2000000 | Q10: =P10/100000 -> 20
A11: 7 | B11: KEMILEMBE MUGELE | C11: 100000 | D11: 200000 | E11: 200000 | F11: 200000 | G11: 200000 | H11: 200000 | P11: =SUM(C11:O11) -> 1100000 | Q11: =P11/100000 -> 11
A12: 8 | B12: MALIKA MANG'ERA | C12: 500000 | D12: 300000 | E12: 400000 | F12: 300000 | G12: 1000000 | H12: 0 | P12: =SUM(C12:O12) -> 2500000 | Q12: =P12/100000 -> 25
A13: 9 | B13: MARY KAPOSWE | C13: 100000 | D13: 200000 | E13: 100000 | F13: 100000 | G13: 0 | H13: 0 | P13: =SUM(C13:O13) -> 500000 | Q13: =P13/100000 -> 5
A14: 10 | B14: EMILY EDWARD | C14: 100000 | D14: 100000 | E14: 100000 | F14: 100000 | G14: 100000 | H14: 0 | P14: =SUM(C14:O14) -> 500000 | Q14: =P14/100000 -> 5
A15: 11 | B15: RAMONA GILBERT | C15: 100000 | D15: 100000 | E15: 200000 | F15: 100000 | G15: 100000 | H15: 0 | P15: =SUM(C15:O15) -> 600000 | Q15: =P15/100000 -> 6
A16: 12 | B16: REGINA CHARLES | C16: 3000000 | D16: 3000000 | E16: 3000000 | F16: 1000000 | G16: 1000000 | H16: 0 | P16: =SUM(C16:O16) -> 11000000 | Q16: =P16/100000 -> 110 | R16: =2000000 -> 2000000 | S16: =P16+R16 -> 13000000
A17: 13 | B17: ROSEMARY LAIZER | C17: 300000 | D17: 100000 | E17: 100000 | F17: 300000 | G17: 0 | H17: 0 | P17: =SUM(C17:O17) -> 800000 | Q17: =P17/100000 -> 8
A18: 14 | B18: RUQAIYA JAWADI | C18: 1000000 | D18: 1000000 | E18: 1000000 | F18: 1000000 | G18: 1000000 | H18: 1000000 | P18: =SUM(C18:O18) -> 6000000 | Q18: =P18/100000 -> 60
A19: 15 | B19: SCHOLASTICA KIVUYO | C19: 200000 | D19: 100000 | E19: 100000 | F19: 200000 | G19: 200000 | H19: 0 | P19: =SUM(C19:O19) -> 800000 | Q19: =P19/100000 -> 8
A20: 16 | B20: HILDA MESULI | C20: 100000 | D20: 100000 | E20: 100000 | F20: 100000 | G20: 100000 | H20: 100000 | P20: =SUM(C20:O20) -> 600000 | Q20: =P20/100000 -> 6
A21: 17 | B21: PATRICIA MGISHA | C21: 200000 | D21: 100000 | E21: 100000 | F21: 100000 | G21: 100000 | H21: 100000 | P21: =SUM(C21:O21) -> 700000 | Q21: =P21/100000 -> 7
A22: 18 | B22: UPENDO MMARY | C22: 300000 | D22: 300000 | E22: 300000 | F22: 200000 | G22: 500000 | H22: 500000 | P22: =SUM(C22:O22) -> 2100000 | Q22: =P22/100000 -> 21
B23: TOTAL | C23: =SUM(C5:C22) -> 8800000 | D23: =SUM(D5:D22) -> 8100000 | E23: =SUM(E5:E22) -> 7300000 | F23: =SUM(F5:F22) -> 5200000 | G23: =SUM(G5:G22) -> 6000000 | H23: =SUM(H5:H22) -> 3200000 | P23: =SUM(P5:P22) -> 38600000 | Q23: =SUM(Q5:Q22) -> 386

Sheet JAMII
D1: MICHANGO MBALIMBALI WANAKIKUNDI WA DIVAS VICOBA
C2: 45627 | D2: 45658 | E2: 45689 | F2: 45717 | G2: 45748 | H2: 45778 | I2: 45809 | J2: 45839 | K2: 45870 | L2: 45901 | M2: 45931 | N2: 45962 | O2: 45992
A3: S/N | B3: JINA | C3: JAMII NA UCHAKAVU | D3: JAMII NA UCHAKAVU | E3: JAMII NA UCHAKAVU | F3: JAMII NA UCHAKAVU | G3: JAMII NA UCHAKAVU | H3: JAMII NA UCHAKAVU | I3: JAMII NA UCHAKAVU | J3: JAMII NA UCHAKAVU | K3: JAMII NA UCHAKAVU | L3: JAMII NA UCHAKAVU | M3: JAMII NA UCHAKAVU | N3: JAMII NA UCHAKAVU | O3: JAMII NA UCHAKAVU | P3: JUMLA
A4: 1 | B4: ALMA MOLLEL | C4: 15000 | D4: 15000 | E4: 15000 | F4: 15000 | G4: 15000 | H4: 15000 | P4: =SUM(C4:O4) -> 90000 | Q4: 0
A5: 2 | B5: BEATRICE MESULI | C5: 15000 | D5: 15000 | E5: 15000 | F5: 15000 | G5: 15000 | P5: =SUM(C5:O5) -> 75000 | Q5: 0
A6: 3 | B6: CATHERINE EDWARD | C6: 15000 | D6: 15000 | E6: 15000 | F6: 15000 | G6: 15000 | H6: 15000 | P6: =SUM(C6:O6) -> 90000 | Q6: 0
A7: 4 | B7: CHRISTINA TAIRO | C7: 15000 | D7: 15000 | E7: 15000 | F7: 15000 | G7: 15000 | H7: 15000 | P7: =SUM(C7:O7) -> 90000 | Q7: 0
A8: 5 | B8: ELIZABETH MOREHE | C8: 15000 | D8: 15000 | E8: 15000 | F8: 15000 | G8: 15000 | H8: 15000 | P8: =SUM(C8:O8) -> 90000 | Q8: 0
A9: 6 | B9: JANETH MKWIZU | C9: 15000 | D9: 15000 | P9: =SUM(C9:O9) -> 30000 | Q9: 0
A10: 7 | B10: KEMILEMBE MUGELE | C10: 15000 | D10: 15000 | E10: 15000 | F10: 15000 | G10: 15000 | H10: 15000 | P10: =SUM(C10:O10) -> 90000 | Q10: 500000
A11: 8 | B11: MALIKA MANG'ERA | C11: 15000 | D11: 15000 | E11: 15000 | F11: 15000 | G11: 15000 | P11: =SUM(C11:O11) -> 75000 | Q11: 0
A12: 9 | B12: MARY KAPOSWE | C12: 15000 | D12: 15000 | E12: 15000 | F12: 15000 | P12: =SUM(C12:O12) -> 60000 | Q12: 0
A13: 10 | B13: EMILY EDWARD | C13: 15000 | D13: 15000 | E13: 15000 | F13: 15000 | G13: 15000 | P13: =SUM(C13:O13) -> 75000 | Q13: 0
A14: 11 | B14: RAMONA GILBERT | C14: 15000 | D14: 15000 | E14: 15000 | F14: 15000 | G14: 15000 | P14: =SUM(C14:O14) -> 75000 | Q14: 0
A15: 12 | B15: REGINA CHARLES | C15: 15000 | D15: 15000 | E15: 15000 | F15: 15000 | G15: 15000 | P15: =SUM(C15:O15) -> 75000 | Q15: 0
A16: 13 | B16: ROSEMARY LAIZER | C16: 15000 | D16: 15000 | E16: 15000 | F16: 15000 | P16: =SUM(C16:O16) -> 60000 | Q16: 0
A17: 14 | B17: RUQAIYA JAWADI | C17: 15000 | D17: 15000 | E17: 15000 | F17: 15000 | G17: 15000 | H17: 15000 | P17: =SUM(C17:O17) -> 90000 | Q17: 0
A18: 15 | B18: SCHOLASTICA KIVUYO | C18: 15000 | D18: 15000 | E18: 15000 | F18: 15000 | G18: 15000 | P18: =SUM(C18:O18) -> 75000 | Q18: 0
A19: 16 | B19: HILDA MESULI | C19: 15000 | D19: 15000 | E19: 15000 | F19: 15000 | G19: 15000 | H19: 15000 | P19: =SUM(C19:O19) -> 90000 | Q19: 0
A20: 17 | B20: PATRICIA MGISHA | C20: 15000 | D20: 15000 | E20: 15000 | F20: 15000 | G20: 15000 | H20: 15000 | P20: =SUM(C20:O20) -> 90000 | Q20: 0
A21: 18 | B21: UPENDO MMARY | C21: 15000 | D21: 15000 | E21: 15000 | F21: 15000 | G21: 15000 | H21: 15000 | P21: =SUM(C21:O21) -> 90000 | Q21: 0
B22: TOTAL | C22: =SUM(C4:C21) -> 270000 | D22: =SUM(D4:D21) -> 270000 | E22: =SUM(E4:E21) -> 255000 | F22: =SUM(F4:F21) -> 255000 | G22: =SUM(G4:G21) -> 225000 | H22: =SUM(H4:H21) -> 135000 | I22: =SUM(I4:I21) -> 0 | J22: =SUM(J4:J21) -> 0 | ... M22: =SUM(M4:M21) -> 0 | N22: =SUM(N4:N16) -> 0 | P22: =SUM(P4:P21) -> 1410000 | Q22: =SUM(Q4:Q21) -> 500000 | R22: =P22-Q22 -> 910000
B26: ASILIMIA ZA MICHANGO MBALIMBALI | C26: KIASI KWA KILA MWANACHAMA | D26: GHARAMA ZAKE
B27: JAMII @ | C27: 10000
B28: UCHAKAVU @ | C28: 5000
B30: MATUMIZI MBALIMBALI | C30: 45658 | D30: 45689 | E30: 45717 | F30: 45748 | G30: 45778 | H30: 45809 | I30: 45839 | J30: 45870 | K30: 45901 | L30: 45931 | M30: 45962 | N30: 45992 | P30: JUMLA
B31: JAMII | C31: 500000
B32: UCHAKAVU

Sheet FAINI
A2: JINA | B2: 45627 | C2: 45658 | D2: 45689 | E2: 45717 | F2: 45748 | G2: 45778 | H2: 45809 | I2: 45839 | J2: 45870 | K2: 45901 | L2: 45931 | M2: 45962 | N2: 45992 | O2: JUMLA YA FAINI | P2: PAID
A3: ALMA MOLLEL | B3: 2000 | C3: 0 | D3: 0 | E3: 0 | F3: 0 | G3: 0 | H3: 0 | I3: 0 | J3: 0 | K3: 0 | L3: 0 | M3: 0 | N3: 0 | O3: =SUM(B3:N3) -> 2000 | P3: =SUM(C3:O3) -> 2000
A4: BEATRICE MESULI | B4: 0 | C4: 0 | D4: 43000 | E4: 46000 | F4: 16000 | G4: 0 | H4: 0 | I4: 0 | J4: 0 | K4: 0 | L4: 0 | M4: 0 | N4: 0 | O4: =SUM(B4:N4) -> 105000 | P4: 9000
A5: CATHERINE EDWARD | B5: 0 | C5: 0 | D5: 4000 | E5: 14000 | F5: 1000 | G5: 0 | H5: 0 | I5: 0 | J5: 0 | K5: 0 | L5: 0 | M5: 0 | N5: 0 | O5: =SUM(B5:N5) -> 19000 | P5: =SUM(C5:O5) -> 38000
A6: CHRISTINA TAIRO | B6: 4000 | C6: 0 | D6: 3000 | E6: 4000 | F6: 3000 | G6: 0 | H6: 0 | I6: 0 | J6: 0 | K6: 0 | L6: 0 | M6: 0 | N6: 0 | O6: =SUM(B6:N6) -> 14000 | P6: =SUM(C6:O6) -> 24000
A7: ELIZABETH MOREHE | B7: 0 | C7: 0 | D7: 0 | E7: 1000 | F7: 3000 | G7: 0 | H7: 0 | I7: 0 | J7: 0 | K7: 0 | L7: 0 | M7: 0 | N7: 0 | O7: =SUM(B7:N7) -> 4000 | P7: 0
A8: JANETH MKWIZU | B8: 55000 | C8: 52000 | D8: 65000 | E8: 65000 | F8: 65000 | G8: 0 | H8: 0 | I8: 0 | J8: 0 | K8: 0 | L8: 0 | M8: 0 | N8: 0 | O8: =SUM(B8:N8) -> 302000 | P8: 0
A9: KEMILEMBE MUGELE | B9: 0 | C9: 0 | D9: 7000 | E9: 4000 | F9: 3000 | G9: 0 | H9: 0 | I9: 0 | J9: 0 | K9: 0 | L9: 0 | M9: 0 | N9: 0 | O9: =SUM(B9:N9) -> 14000 | P9: 7000
A10: MALIKA MANG'ERA | B10: 3000 | C10: 3000 | D10: 48000 | E10: 43000 | F10: 40000 | G10: 0 | H10: 0 | I10: 0 | J10: 0 | K10: 0 | L10: 0 | M10: 0 | N10: 0 | O10: =SUM(B10:N10) -> 137000 | P10: 11000
A11: MARY KAPOSWE | B11: 5000 | C11: 5000 | D11: 40000 | E11: 69000 | F11: 40000 | G11: 0 | H11: 0 | I11: 0 | J11: 0 | K11: 0 | L11: 0 | M11: 0 | N11: 0 | O11: =SUM(B11:N11) -> 159000 | P11: 39000
A12: EMILY EDWARD | B12: 3000 | C12: 40000 | D12: 48000 | E12: 43000 | F12: 40000 | G12: 0 | H12: 0 | I12: 0 | J12: 0 | K12: 0 | L12: 0 | M12: 0 | N12: 0 | O12: =SUM(B12:N12) -> 174000 | P12: 11000
A13: RAMONA GILBERT | B13: 0 | C13: 0 | D13: 0 | E13: 0 | F13: 0 | G13: 0 | H13: 0 | I13: 0 | J13: 0 | K13: 0 | L13: 0 | M13: 0 | N13: 0 | O13: =SUM(B13:N13) -> 0 | P13: 0
A14: REGINA CHARLES | B14: 0 | C14: 0 | D14: 0 | E14: 3000 | F14: 1000 | G14: 0 | H14: 0 | I14: 0 | J14: 0 | K14: 0 | L14: 0 | M14: 0 | N14: 0 | O14: =SUM(B14:N14) -> 4000 | P14: 0
A15: ROSEMARY LAIZER | B15: 15000 | C15: 40000 | D15: 44000 | E15: 14000 | F15: 40000 | G15: 0 | H15: 0 | I15: 0 | J15: 0 | K15: 0 | L15: 0 | M15: 0 | N15: 0 | O15: =SUM(B15:N15) -> 153000 | P15: 4000
A16: RUQAIYA JAWADI | B16: 40000 | C16: 40000 | D16: 5000 | E16: 50000 | F16: 39000 | G16: 0 | H16: 0 | I16: 0 | J16: 0 | K16: 0 | L16: 0 | M16: 0 | N16: 0 | O16: =SUM(B16:N16) -> 174000 | P16: 15000
A17: SCHOLASTICA KIVUYO | B17: 3000 | C17: 52000 | D17: 45000 | E17: 15000 | F17: 43000 | G17: 0 | H17: 0 | I17: 0 | J17: 0 | K17: 0 | L17: 0 | M17: 0 | N17: 0 | O17: =SUM(B17:N17) -> 158000 | P17: 13000
A18: HILDA MESULI | B18: 42000 | C18: 40000 | D18: 43000 | E18: 40000 | F18: 40000 | G18: 0 | H18: 0 | I18: 0 | J18: 0 | K18: 0 | L18: 0 | M18: 0 | N18: 0 | O18: =SUM(B18:N18) -> 205000 | P18: 5000
... A20: UPENDO MMARY | B20: 3000 | C20: 40000 | D20: 55000 | E20: 0 | F20: 41000 | G20: 0 | H20: 0 | I20: 0 | J20: 0 | K20: 0 | L20: 0 | M20: 0 | N20: 0 | O20: =SUM(B20:N20) -> 139000 | P20: 19000
A21: TOTAL | B21: =SUM(B3:B20) -> 215000 | C21: =SUM(C3:C20) -> 352000 | D21: =SUM(D3:D20) -> 453000 | E21: =SUM(E3:E20) -> 411000 | F21: =SUM(F3:F20) -> 475000 | H21: =SUM(H3:H20) -> 0 | I21: =SUM(I3:I20) -> 0 | J21: =SUM(J3:J20) -> 0 | K21: =SUM(K3:K20) -> 0 | L21: =SUM(L3:L20) -> 0 | N21: =SUM(N3:N20) -> 0 | O21: =SUM(O3:O20) -> 1906000
A23: KUCHELEWA KWA HISA NI TSH.1,000 KWA KILA SIKU INAYOZIDI
A24: KUTOKUHUDHURIA MKUTANO 15,000
A25: KUCHELEWESHA REJESHO LA MKOPO WA MWEZI,ADHABU NI FAINI YA 10,000 KILA WEEK INAYOZIDI

Sheet MIKOPO NA RIBA
A2: year 2024 | C2: CHRISTINA | D2: 45181 | G2: ELIZABETH | H2: 45208 | K2: ROSEMARY | L2: 45245 | O2: PATRICIA | P2: 45267 | S2: EMILY | T2: 45278 | W2: RAMONA | AA2: RUQAIYA | AE2: CATHERINE | AI2: KEMILEMBE | AM2: REGINA | AQ2: Upendo | AU2: Alma | AY2: Beatrice 2 | BC2: Schola 2 | BG2: Mary 2 | BK2: Janeth 2 | BO2: RAMONA 2 | BS2: RUQAIYA 2
A3: DATES | B3: MKOPO | C3: RIBA | D3: REJESHO | E3: KIASI BAKI | F3: MKOPO | G3: RIBA | H3: REJESHO | I3: KIASI BAKI | J3: MKOPO | K3: RIBA | L3: REJESHO | M3: KIASI BAKI | N3: MKOPO | O3: RIBA | P3: REJESHO | Q3: KIASI BAKI | R3: MKOPO | S3: RIBA | T3: REJESHO | U3: KIASI BAKI | V3: MKOPO | W3: RIBA | X3: REJESHO | Y3: KIASI BAKI | Z3: MKOPO | AA3: RIBA | AB3: REJESHO | AC3: KIASI BAKI | AD3: MKOPO | AE3: RIBA | AF3: REJESHO | AG3: KIASI BAKI | AH3: MKOPO | AI3: RIBA | AJ3: REJESHO | AK3: KIASI BAKI | AL3: MKOPO | AM3: RIBA | AN3: REJESHO | AO3: KIASI BAKI | AP3: MKOPO | AQ3: RIBA | AR3: REJESHO | AS3: KIASI BAKI | AT3: MKOPO | AU3: RIBA | AV3: REJESHO | AW3: KIASI BAKI | AX3: MKOPO | AY3: RIBA | AZ3: REJESHO | BA3: KIASI BAKI | BB3: MKOPO | BC3: RIBA | BD3: REJESHO | BE3: KIASI BAKI | BF3: MKOPO | BG3: RIBA | BH3: REJESHO | BI3: KIASI BAKI | BJ3: MKOPO | BK3: RIBA | BL3: REJESHO | BM3: KIASI BAKI | BN3: MKOPO | BO3: RIBA | BP3: REJESHO | BQ3: KIASI BAKI | BR3: MKOPO | BS3: RIBA | BT3: REJESHO | BU3: KIASI BAKI
A4: OPEN/Balance | B4: 10000000 | C4: 1000000 | E4: 9090000 | F4: 10000000 | G4: 1000000 | I4: 9774000 | J4: 10000000 | K4: 1000000 | M4: 11000000 | N4: 10000000 | O4: 1000000 | Q4: 11000000 | R4: 6000000 | S4: 600000 | U4: 6600000
A5: 45292 | D5: 650000 | E5: =E4-D5 -> 8440000 | H5: 611000 | I5: =I4-H5 -> 9163000 | L5: 1000000 | M5: =M4-L5 -> 10000000 | P5: 612000 | Q5: =Q4-P5 -> 10388000 | T5: 550000 | U5: =U4-T5 -> 6050000 | V5: 10000000 | W5: 1000000 | Y5: =V5+W5 -> 11000000
A6: 45323 | D6: 650000 | E6: =E5-D6 -> 7790000 | H6: 611000 | I6: =I5-H6 -> 8552000 | L6: 700000 | M6: =M5-L6 -> 9300000 | P6: 612000 | Q6: =Q5-P6 -> 9776000 | T6: 550000 | U6: =U5-T6 -> 5500000 | X6: 1000000 | Y6: =Y5-X6 -> 10000000 | Z6: 10000000 | AA6: 1000000 | AC6: =Z6+AA6 -> 11000000 | AD6: 10000000 | AE6: 1000000 | AG6: =AD6+AE6 -> 11000000
A7: 45352 | D7: 500000 | E7: =E6-D7 -> 7290000 | H7: 611000 | I7: =I6-H7 -> 7941000 | L7: 700000 | M7: =M6-L7 -> 8600000 | P7: 612000 | Q7: =Q6-P7 -> 9164000 | T7: 550000 | U7: =U6-T7 -> 4950000 | X7: 1000000 | Y7: =Y6-X7 -> 9000000 | AB7: 1000000 | AC7: =AC6-AB7 -> 10000000 | AF7: 612000 | AG7: =AG6-AF7 -> 10388000 | AH7: 10000000 | AI7: 1000000 | AK7: =AH7+AI7 -> 11000000 | AO7: =AL7+AM7 -> 0 | AS7: =AP7+AQ7 -> 0 | AW7: =AT7+AU7 -> 0
A8: 45383 | D8: 0 | E8: =E7-D8 -> 7290000 | H8: 611000 | I8: =I7-H8 -> 7330000 | L8: 612000 | M8: =M7-L8 -> 7988000 | P8: 612000 | Q8: =Q7-P8 -> 8552000 | T8: 550000 | U8: =U7-T8 -> 4400000 | X8: 1000000 | Y8: =Y7-X8 -> 8000000 | AB8: 1000000 | AC8: =AC7-AB8 -> 9000000 | AF8: 612000 | AG8: =AG7-AF8 -> 9776000 | AJ8: 612000 | AK8: =AK7-AJ8 -> 10388000 | AL8: 10000000 | AM8: 1000000 | AO8: =AL8+AM8 -> 11000000 | AP8: 10000000 | AQ8: 1000000 | AS8: =AP8+AQ8 -> 11000000 | AW8: =AT8+AU8 -> 0
A9: 45413 | D9: 716000 | E9: =E8-D9 -> 6574000 | H9: 611000 | I9: =I8-H9 -> 6719000 | L9: 600000 | M9: =M8-L9 -> 7388000 | P9: 612000 | Q9: =Q8-P9 -> 7940000 | T9: 550000 | U9: =U8-T9 -> 3850000 | X9: 700000 | Y9: =Y8-X9 -> 7300000 | AB9: 1000000 | AC9: =AC8-AB9 -> 8000000 | AF9: 612000 | AG9: =AG8-AF9 -> 9164000 | AJ9: 612000 | AK9: =AK8-AJ9 -> 9776000 | AN9: 620000 | AO9: =AO8-AN9 -> 10380000 | AR9: 700000 | AS9: =AS8-AR9 -> 10300000 | AT9: 10000000 | AU9: 1000000 | AV9: 0 | AW9: =AT9+AU9-AV9 -> 11000000
A10: 45444 | D10: 1200000 | E10: =E9-D10 -> 5374000 | H10: 611000 | I10: =I9-H10 -> 6108000 | L10: 612000 | M10: =M9-L10 -> 6776000 | P10: 612000 | Q10: =Q9-P10 -> 7328000 | T10: 550000 | U10: =U9-T10 -> 3300000 | X10: 1000000 | Y10: =Y9-X10 -> 6300000 | AB10: 1000000 | AC10: =AC9-AB10 -> 7000000 | AF10: 612000 | AG10: =AG9-AF10 -> 8552000 | AJ10: 612000 | AK10: =AK9-AJ10 -> 9164000 | AN10: 600000 | AO10: =AO9-AN10 -> 9780000 | AR10: 700000 | AS10: =AS9-AR10 -> 9600000 | AV10: 612000 | AW10: =AW9-AV10 -> 10388000 | AX10: 15000000 | AY10: 1500000 | BA10: =AX10+AY10 -> 16500000 | BB10: 15000000 | BC10: 1500000 | BE10: =BB10+BC10 -> 16500000 | BI10: =BF10+BG10 -> 0
A11: 45474 | D11: 612000 | E11: =E10-D11 -> 4762000 | H11: 611000 | I11: =I10-H11 -> 5497000 | L11: 612000 | M11: =M10-L11 -> 6164000 | P11: 612000 | Q11: =Q10-P11 -> 6716000 | T11: 550000 | U11: =U10-T11 -> 2750000 | X11: 1000000 | Y11: =Y10-X11 -> 5300000 | AB11: 1000000 | AC11: =AC10-AB11 -> 6000000 | AF11: 612000 | AG11: =AG10-AF11 -> 7940000 | AJ11: 612000 | AK11: =AK10-AJ11 -> 8552000 | AN11: 620000 | AO11: =AO10-AN11 -> 9160000 | AS11: =AS10-AR11 -> 9600000 | AV11: 612000 | AW11: =AW10-AV11 -> 9776000 | AZ11: 718000 | BA11: =BA10-AZ11 -> 15782000 | BD11: 1000000 | BE11: =BE10-BD11 -> 15500000 | BF11: 20000000 | BG11: 2000000 | BI11: =BF11+BG11 -> 22000000
A12: 45505 | D12: 630000 | E12: =E11-D12 -> 4132000 | H12: 610000 | I12: =I11-H12 -> 4887000 | L12: 612000 | M12: =M11-L12 -> 5552000 | P12: 612000 | Q12: =Q11-P12 -> 6104000 | T12: 2750000 | U12: =U11-T12 -> 0 | X12: 1000000 | Y12: =Y11-X12 -> 4300000 | AB12: 1000000 | AC12: =AC11-AB12 -> 5000000 | AF12: 612000 | AG12: =AG11-AF12 -> 7328000 | AJ12: 612000 | AK12: =AK11-AJ12 -> 7940000 | AN12: 612000 | AO12: =AO11-AN12 -> 8548000 | AS12: =AS11-AR12 -> 9600000 | AV12: 612000 | AW12: =AW11-AV12 -> 9164000 | AZ12: 718000 | BA12: =BA11-AZ12 -> 15064000 | BD12: 800000 | BE12: =BE11-BD12 -> 14700000 | BH12: 1300000 | BI12: =BI11-BH12 -> 20700000 | BJ12: 20000000 | BK12: 2000000 | BM12: =BJ12+BK12 -> 22000000
A13: 45536 | D13: 700000 | E13: =E12-D13 -> 3432000 | H13: 612000 | I13: =I12-H13 -> 4275000 | L13: 612000 | M13: =M12-L13 -> 4940000 | P13: 612000 | Q13: =Q12-P13 -> 5492000 | U13: =U12-T13 -> 0 | X13: 4300000 | Y13: =Y12-X13 -> 0 | AB13: 1000000 | AC13: =AC12-AB13 -> 4000000 | AF13: 612000 | AG13: =AG12-AF13 -> 6716000 | AJ13: 612000 | AK13: =AK12-AJ13 -> 7328000 | AN13: 612000 | AO13: =AO12-AN13 -> 7936000 | AS13: =AS12-AR13 -> 9600000 | AV13: 612000 | AW13: =AW12-AV13 -> 8552000 | AZ13: 717000 | BA13: =BA12-AZ13 -> 14347000 | BD13: 800000 | BE13: =BE12-BD13 -> 13900000 | BH13: 1300000 | BI13: =BI12-BH13 -> 19400000 | BM13: =BM12-BL13 -> 22000000 | BN13: 20000000 | BO13: 2000000 | BP13: 1000000 | BQ13: =BN13+BO13-BP13 -> 21000000 | BU13: =BR13+BS13-BT13 -> 0
A14: 45566 | D14: 615000 | E14: =E13-D14 -> 2817000 | H14: 612000 | I14: =I13-H14 -> 3663000 | M14: =M13-L14 -> 4940000 | P14: 600000 | Q14: =Q13-P14 -> 4892000 | U14: =U13-T14 -> 0 | Y14: =Y13-X14 -> 0 | AB14: 1000000 | AC14: =AC13-AB14 -> 3000000 | AF14: 612000 | AG14: =AG13-AF14 -> 6104000 | AJ14: 612000 | AK14: =AK13-AJ14 -> 6716000 | AN14: 612000 | AO14: =AO13-AN14 -> 7324000 | AR14: 1000000 | AS14: =AS13-AR14 -> 8600000 | AV14: 612000 | AW14: =AW13-AV14 -> 7940000 | AZ14: 517000 | BA14: =BA13-AZ14 -> 13830000 | BD14: 800000 | BE14: =BE13-BD14 -> 13100000 | BH14: 1300000 | BI14: =BI13-BH14 -> 18100000 | BM14: =BM13-BL14 -> 22000000 | BP14: 1250000 | BQ14: =BQ13-BP14 -> 19750000 | BR14: 22000000 | BS14: 2200000 | BT14: 0 | BU14: =BR14+BS14 -> 24200000
A15: 45597 | D15: 600000 | E15: =E14-D15 -> 2217000 | H15: 615000 | I15: =I14-H15 -> 3048000 | M15: =M14-L15 -> 4940000 | P15: 600000 | Q15: =Q14-P15 -> 4292000 | U15: =U14-T15 -> 0 | Y15: =Y14-X15 -> 0 | AB15: 3000000 | AC15: =AC14-AB15 -> 0 | AF15: 612000 | AG15: =AG14-AF15 -> 5492000 | AJ15: 612000 | AK15: =AK14-AJ15 -> 6104000 | AN15: 600000 | AO15: =AO14-AN15 -> 6724000 | AS15: =AS14-AR15 -> 8600000 | AV15: 612000 | AW15: =AW14-AV15 -> 7328000 | AZ15: 917000 | BA15: =BA14-AZ15 -> 12913000 | BD15: 800000 | BE15: =BE14-BD15 -> 12300000 | BH15: 1300000 | BI15: =BI14-BH15 -> 16800000 | BL15: 2000000 | BM15: =BM14-BL15 -> 20000000 | BP15: 2000000 | BQ15: =BQ14-BP15 -> 17750000 | BT15: 1862000 | BU15: =BU14-BT15 -> 22338000
A16: 45627 | H16: 616000 | I16: =I15-H16 -> 2432000 | AF16: 612000 | AG16: =AG15-AF16 -> 4880000 | AJ16: 612000 | AK16: =AK15-AJ16 -> 5492000 | AN16: 612000 | AO16: =AO15-AN16 -> 6112000 | AV16: 620000 | AW16: =AW15-AV16 -> 6708000 | AZ16: 717000 | BA16: =BA15-AZ16 -> 12196000 | BD16: 800000 | BE16: =BE15-BD16 -> 11500000 | BL16: 2000000 | BM16: =BM15-BL16 -> 18000000 | BP16: 1250000 | BQ16: =BQ15-BP16 -> 16500000 | BT16: 1862000 | BU16: =BU15-BT16 -> 20476000
A17: TOTAL | B17: =SUM(B4:B15) -> 10000000 | C17: =SUM(C4:C15) -> 1000000 | D17: =SUM(D4:D15) -> 6873000 | F17: =SUM(F4:F15) -> 10000000 | G17: =SUM(G4:G15) -> 1000000 | H17: =SUM(H4:H16) -> 7342000 | J17: =SUM(J4:J15) -> 10000000 | K17: =SUM(K4:K15) -> 1000000 | L17: =SUM(L4:L15) -> 6060000 | N17: =SUM(N4:N15) -> 10000000 | O17: =SUM(O4:O15) -> 1000000 | P17: =SUM(P4:P15) -> 6708000 | R17: =SUM(R4:R15) -> 6000000 | S17: =SUM(S4:S15) -> 600000 | T17: =SUM(T4:T15) -> 6600000 | V17: =SUM(V4:V15) -> 10000000 | W17: =SUM(W4:W15) -> 1000000 | X17: =SUM(X4:X15) -> 11000000 | Z17: =SUM(Z4:Z15) -> 10000000 | AA17: =SUM(AA4:AA15) -> 1000000 | AB17: =SUM(AB4:AB15) -> 11000000 | AD17: =SUM(AD4:AD15) -> 10000000 | AE17: =SUM(AE4:AE15) -> 1000000 | AF17: =SUM(AF4:AF16) -> 6120000 | AH17: =SUM(AH4:AH15) -> 10000000 | AI17: =SUM(AI4:AI15) -> 1000000 | AJ17: =SUM(AJ4:AJ16) -> 5508000 | AL17: =SUM(AL4:AL15) -> 10000000 | AM17: =SUM(AM4:AM15) -> 1000000 | AN17: =SUM(AN4:AN16) -> 4888000 | AP17: =SUM(AP4:AP15) -> 10000000 | AQ17: =SUM(AQ4:AQ15) -> 1000000 | AR17: =SUM(AR4:AR15) -> 2400000 | AT17: =SUM(AT4:AT15) -> 10000000 | AU17: =SUM(AU4:AU15) -> 1000000 | AV17: =SUM(AV4:AV16) -> 4292000 | AX17: =SUM(AX4:AX15) -> 15000000 | AY17: =SUM(AY4:AY15) -> 1500000 | AZ17: =SUM(AZ4:AZ16) -> 4304000 | BB17: =SUM(BB4:BB15) -> 15000000 | BC17: =SUM(BC4:BC15) -> 1500000 | BD17: =SUM(BD4:BD16) -> 5000000 | BF17: =SUM(BF4:BF15) -> 20000000 | BG17: =SUM(BG4:BG15) -> 2000000 | BH17: =SUM(BH4:BH15) -> 5200000 | BJ17: =SUM(BJ4:BJ15) -> 20000000 | BK17: =SUM(BK4:BK15) -> 2000000 | BL17: =SUM(BL4:BL15) -> 2000000 | BN17: =SUM(BN4:BN15) -> 20000000 | BO17: =SUM(BO4:BO15) -> 2000000 | BP17: =SUM(BP4:BP16) -> 5500000 | BR17: =SUM(BR4:BR15) -> 22000000 | BS17: =SUM(BS4:BS15) -> 2200000 | BT17: =SUM(BT4:BT16) -> 3724000
A21: year 2025
C22: CHRISTINA | D22: 45181 | G22: ELIZABETH | H22: 45208 | K22: ROSEMARY | L22: 45245 | O22: PATRICIA | P22: 45267 | S22: RAMONA | W22: RUQAIYA | AA22: CATHERINE | AE22: KEMILEMBE | AI22: REGINA | AM22: Upendo | AQ22: Alma | AU22: Beatrice 2 | AY22: Schola 2 | BC22: Mary 2 | BG22: Janeth 2 | BK22: HILDA | BO22: EMILY2 | BS22: MALIKA2 | BW22: CHRISTINA 2 | CA22: ALMA 2
A23: DATES | B23: MKOPO | C23: RIBA | D23: REJESHO | E23: KIASI BAKI | F23: MKOPO | G23: RIBA | H23: REJESHO | I23: KIASI BAKI | J23: MKOPO | K23: RIBA | L23: REJESHO | M23: KIASI BAKI | N23: MKOPO | O23: RIBA | P23: REJESHO | Q23: KIASI BAKI | R23: MKOPO | S23: RIBA | T23: REJESHO | U23: KIASI BAKI | V23: MKOPO | W23: RIBA | X23: REJESHO | Y23: KIASI BAKI | Z23: MKOPO | AA23: RIBA | AB23: REJESHO | AC23: KIASI BAKI | AD23: MKOPO | AE23: RIBA | AF23: REJESHO | AG23: KIASI BAKI | AH23: MKOPO | AI23: RIBA | AJ23: REJESHO | AK23: KIASI BAKI | AL23: MKOPO | AM23: RIBA | AN23: REJESHO | AO23: KIASI BAKI | AP23: MKOPO | AQ23: RIBA | AR23: REJESHO | AS23: KIASI BAKI | AT23: MKOPO | AU23: RIBA | AV23: REJESHO | AW23: KIASI BAKI | AX23: MKOPO | AY23: RIBA | AZ23: REJESHO | BA23: KIASI BAKI | BB23: MKOPO | BC23: RIBA | BD23: REJESHO | BE23: KIASI BAKI | BF23: MKOPO | BG23: RIBA | BH23: REJESHO | BI23: KIASI BAKI | BJ23: MKOPO | BK23: RIBA | BL23: REJESHO | BM23: KIASI BAKI | BN23: MKOPO | BO23: RIBA | BP23: REJESHO | BQ23: KIASI BAKI | BR23: MKOPO | BS23: RIBA | BT23: REJESHO | BU23: KIASI BAKI | BV23: MKOPO | BW23: RIBA | BX23: REJESHO | BY23: KIASI BAKI | BZ23: MKOPO | CA23: RIBA | CB23: REJESHO | CC23: KIASI BAKI
A24: OPEN/Balance | B24: 2217000 | E24: 2217000 | F24: 2432000 | I24: 2432000 | J24: 4940000 | M24: 4940000 | N24: 4292000 | Q24: 4292000 | R24: 16500000 | U24: =R24+S24-T24 -> 16500000 | V24: 20476000 | Y24: =V24+W24-X24 -> 20476000 | Z24: 4880000 | AC24: =Z24+AA24-AB24 -> 4880000 | AD24: 5493966.4 | AG24: 5496600.3 | AH24: 6112000 | AK24: =AH24+AI24 -> 6112000 | AL24: 8600000 | AO24: 8600000 | AP24: 6708000 | AS24: 6708000 | AT24: 12196000 | AW24: 12196000 | AX24: 11500000 | BA24: 11500000 | BB24: 16800000 | BE24: =BB24+BC24 -> 16800000 | BF24: 18000000 | BI24: 18000000 | BJ24: 3044000 | BM24: 3044000
A25: 45658 | D25: 1700000 | E25: =E24-D25 -> 517000 | H25: 620000 | I25: =I24-H25 -> 1812000 | N25: 4292000 | P25: 600000 | Q25: =Q24-P25 -> 3692000 | U25: =U24-T25 -> 16500000 | Y25: =Y24-X25 -> 20476000 | AB25: 612000 | AC25: =AC24-AB25 -> 4268000 | AF25: 612000 | AG25: =AG24-AF25 -> 4884600.3 | AJ25: 612000 | AK25: =AK24-AJ25 -> 5500000 | AO25: =AO24-AN25 -> 8600000 | AR25: 620000 | AS25: =AS24-AR25 -> 6088000 | AV25: 712000 | AW25: =AW24-AV25 -> 11484000 | BA25: =BA24-AZ25 -> 11500000 | BD25: 2600000 | BE25: =BE24-BD25 -> 14200000 | BI25: =BI24-BH25 -> 18000000 | BM25: =BM24-BL25 -> 3044000 | BN25: 13000000 | BO25: 1300000 | BQ25: =BN25+BO25-BP25 -> 14300000
A26: 45689 | D26: 517000 | E26: =E25-D26 -> 0 | H26: 620000 | I26: =I25-H26 -> 1192000 | N26: 4292000 | P26: 1200000 | Q26: =Q25-P26 -> 2492000 | T26: 2000000 | U26: =U25-T26 -> 14500000 | X26: 1862000 | Y26: =Y25-X26 -> 18614000 | AB26: 612000 | AC26: =AC25-AB26 -> 3656000 | AF26: 612000 | AG26: =AG25-AF26 -> 4272600.3 | AJ26: 600000 | AK26: =AK25-AJ26 -> 4900000 | AO26: =AO25-AN26 -> 8600000 | AR26: 1000000 | AS26: =AS25-AR26 -> 5088000 | AV26: 717000 | AW26: =AW25-AV26 -> 10767000 | BD26: 3000000 | BE26: =BE25-BD26 -> 11200000 | BR26: 22000000 | BS26: 2200000 | BU26: =BR26+BS26-BT26 -> 24200000
A27: 45717 | H27: 620000 | I27: =I26-H27 -> 572000 | N27: 4292000 | P27: 2400000 | Q27: =Q26-P27 -> 92000 | T27: 1300000 | U27: =U26-T27 -> 13200000 | X27: 1862000 | Y27: =Y26-X27 -> 16752000 | AB27: 612000 | AC27: =AC26-AB27 -> 3044000 | AF27: 612000 | AG27: =AG26-AF27 -> 3660600.3 | AJ27: 600000 | AK27: =AK26-AJ27 -> 4300000 | AN27: 1000000 | AO27: =AO26-AN27 -> 7600000 | AR27: 2000000 | AS27: =AS26-AR27 -> 3088000 | BV27: 20000000 | BW27: 2000000 | BY27: =BV27+BW27 -> 22000000
A28: 45748 | H28: 572000 | I28: =I27-H28 -> 0 | M28: 612000 | N28: =N27-M28 -> 3680000 | T28: 1500000 | U28: =U27-T28 -> 11700000 | X28: 1862000 | Y28: =Y27-X28 -> 14890000 | AB28: 612000 | AC28: =AC27-AB28 -> 2432000 | AF28: 612000 | AG28: =AG27-AF28 -> 3048600.3 | AJ28: 612000 | AK28: =AK27-AJ28 -> 3688000 | AR28: 3088000 | AS28: =AS27-AR28 -> 0 | BX28: 2750000 | BY28: =BY27-BX28 -> 19250000 | BZ28: 16500000 | CA28: 1650000 | CC28: =BZ28+CA28-CB28 -> 18150000
A29: 45778 | X29: 1862000 | Y29: =Y28-X29 -> 13028000 | BX29: 2450000 | BY29: =BY28-BX29 -> 16800000 | CB29: 1250000 | CC29: =CC28-CB29 -> 16900000
A30: 45809
A31: 45839
A32: 45870
A33: 45901
A34: 45931
A35: 45962
A36: 45992
A37: TOTAL | B37: =SUM(B24:B35) -> 2217000 | C37: =SUM(C24:C35) -> 0 | D37: =SUM(D24:D35) -> 2217000 | F37: =SUM(F24:F35) -> 2432000 | G37: =SUM(G24:G35) -> 0 | H37: =SUM(H24:H36) -> 2432000 | J37: =SUM(J24:J35) -> 4940000 | K37: =SUM(K24:K35) -> 0 | L37: =SUM(L24:L35) -> 0 | N37: =SUM(N24:N35) -> 20848000 | O37: =SUM(O24:O35) -> 0 | P37: =SUM(P24:P35) -> 4200000 | R37: =SUM(R24:R35) -> 16500000 | S37: =SUM(S24:S35) -> 0 | T37: =SUM(T24:T35) -> 4800000 | V37: =SUM(V24:V35) -> 20476000 | W37: =SUM(W24:W35) -> 0 | X37: =SUM(X24:X36) -> 7448000 | Z37: =SUM(Z24:Z35) -> 4880000 | AA37: =SUM(AA24:AA35) -> 0 | AB37: =SUM(AB24:AB35) -> 2448000 | AD37: =SUM(AD24:AD35) -> 5493966.4 | AE37: =SUM(AE24:AE35) -> 0 | AF37: =SUM(AF24:AF35) -> 2448000 | AH37: =SUM(AH24:AH35) -> 6112000 | AI37: =SUM(AI24:AI35) -> 0 | AJ37: =SUM(AJ24:AJ35) -> 2424000 | AL37: =SUM(AL24:AL35) -> 8600000 | AM37: =SUM(AM24:AM35) -> 0 | AN37: =SUM(AN24:AN35) -> 1000000 | AP37: =SUM(AP24:AP35) -> 6708000 | AQ37: =SUM(AQ24:AQ35) -> 0 | AR37: =SUM(AR24:AR36) -> 6708000 | AT37: =SUM(AT24:AT35) -> 12196000 | AU37: =SUM(AU24:AU35) -> 0 | AV37: =SUM(AV24:AV35) -> 1429000 | AX37: =SUM(AX24:AX35) -> 11500000 | AY37: =SUM(AY24:AY35) -> 0 | AZ37: =SUM(AZ24:AZ35) -> 0 | BB37: =SUM(BB24:BB35) -> 16800000 | BC37: =SUM(BC24:BC35) -> 0 | BD37: =SUM(BD24:BD35) -> 5600000 | BF37: =SUM(BF24:BF35) -> 18000000 | BG37: =SUM(BG24:BG35) -> 0 | BH37: =SUM(BH24:BH35) -> 0 | BJ37: =SUM(BJ24:BJ35) -> 3044000 | BK37: =SUM(BK24:BK35) -> 0 | BL37: =SUM(BL24:BL36) -> 0 | BN37: =SUM(BN24:BN35) -> 13000000 | BO37: =SUM(BO24:BO35) -> 1300000 | BP37: =SUM(BP24:BP36) -> 0 | BR37: =SUM(BR24:BR35) -> 22000000 | BS37: =SUM(BS24:BS35) -> 2200000 | BT37: =SUM(BT24:BT36) -> 0 | BV37: 22000000 | BW37: 2200000 | BX37: 0 | BZ37: 22000000 | CA37: 2200000 | CB37: 0

Sheet MAREJESHO
F1: 45784 | J1: 45784
C2: ROUND ONE | L2: ROUND TWO
A3: NO. | B3: MAJINA | C3: KIWANGO CHA MKOPO | D3: MARAJESHO | E3: KIASI KILICHOBAKI | F3: TAREHE YA REJESHO | G3: deadline | I3: NO. | J3: MAJINA | K3: KIWANGO CHA MKOPO | L3: MARAJESHO | M3: KIASI KILICHOBAKI | N3: TAREHE YA REJESHO | O3: deadline
A4: 1 | B4: BEATRICE MESULI | C4: 9900000 | D4: =C4-E4 -> 9900000 | E4: =2955000-612000-612000-1731000 -> 0 | F4: 45418 | G4: 13th | I4: 1 | J4: BEATRICE MESULI | K4: 16500000 | L4: =718000+718000+718000+517000+917000+717000+717000+717000 -> 5739000 | M4: =K4-L4 -> 10761000 | N4: 45450 | O4: 14th
A5: 2 | B5: MARY KAPOSWE | C5: 11000000 | D5: =C5-E5 -> 11000000 | E5: =4267000-612000-612000-3000000-10000-33000 -> 0 | F5: 45418 | G5: 13th | I5: 2 | J5: MARY KAPOSWE | K5: 22000000 | L5: =1300000+1300000+1300000+1300000+2600000+3000000 -> 10800000 | M5: =K5-L5 -> 11200000 | N5: 45490 | O5: 24th
A6: 3 | B6: SCHOLA KIVUYO | C6: 11000000 | D6: =C6-E6 -> 11000000 | E6: =4000000-1000000-3000000 -> 0 | F6: 45451 | G6: 15th | I6: 3 | J6: SCHOLA KIVUYO | K6: 16500000 | L6: =1000000+800000+800000+1600000+800000 -> 5000000 | M6: =K6-L6 -> 11500000 | N6: 45454 | O6: 15th
A7: 4 | B7: JANETH SALEHE | C7: 11000000 | D7: =C7-E7 -> 11000000 | E7: =5000000-2000000-2000000-1000000 -> 0 | F7: 45482 | G7: 16th | I7: 4 | J7: JANETH SALEHE | K7: 22000000 | L7: =2000000+2000000 -> 4000000 | M7: =K7-L7 -> 18000000 | N7: 45516 | O7: 19th
A8: 5 | B8: MALIKA MANG'ERA | C8: 11000000 | D8: =C8-E8 -> 11000000 | E8: =5328000-612000-716000-612000-2000000-1388000 -> 0 | F8: 45519 | G8: 22th | I8: 5 | J8: MALIKA MANG'ERA | K8: 24200000 | M8: =K8-L8 -> 24200000 | N8: 45695 | O8: 14TH
A9: 6 | B9: HILDA MESULI | C9: 11000000 | D9: =C9-E9 -> 7956000 | E9: =7328000-612000-612000-612000-612000-612000-612000-612000 -> 3044000 | F9: 45549 | G9: 21th | I9: 6 | J9: HILDA MESULI | M9: =K9-L9 -> 0
A10: 7 | B10: CHRISTINA TAIRO | C10: 11000000 | D10: =C10-E10 -> 11000000 | E10: =7290000-716000-1200000-612000-630000-700000-615000-600000-1700000-517000 -> 0 | F10: 45547 | G10: 19th | I10: 7 | J10: CHRISTINA TAIRO | K10: 22000000 | L10: =2750000+2450000 -> 5200000 | M10: =K10-L10 -> 16800000 | N10: 45727 | O10: 18TH
A11: 8 | B11: ELIZABETH MOREHE | C11: 11000000 | D11: =C11-E11 -> 11000000 | E11: =7330000-611000-611000-611000-610000-612000-612000-615000-616000-620000-620000-620000-572000 -> 0 | F11: 45574 | G11: 15th | I11: 8 | J11: ELIZABETH MOREHE | M11: =K11-L11 -> 0
A12: 9 | B12: ROSEMARY LAIZER | C12: 11000000 | D12: =C12-E12 -> 6672000 | E12: =7988000-600000-612000-1224000-612000-612000 -> 4328000 | F12: 45611 | G12: 22th | I12: 9 | J12: ROSEMARY LAIZER | M12: =K12-L12 -> 0
A13: 10 | B13: PATRICIA MUGISHA | C13: 11000000 | D13: =C13-E13 -> 10908000 | E13: =9164000-612000-612000-612000-612000-612000-612000-1200000-600000-1200000-2400000 -> 92000 | F13: 45633 | G13: 14th | I13: 10 | J13: PATRICIA MUGISHA | K13: 3300000 | M13: =K13-L13 -> 3300000 | N13: may
A14: 11 | B14: EMILY EDWARD | C14: 6600000 | D14: =C14-E14 -> 6600000 | E14: =4950000-550000-550000-550000-550000-2750000 -> 0 | F14: 45644 | G14: 25th | I14: 11 | J14: EMILY EDWARD | K14: 14300000 | M14: =K14-L14 -> 14300000 | N14: 46021 | O14: 6TH
A15: 12 | B15: RAMONA GILBERT | C15: 11000000 | D15: =C15-E15 -> 11000000 | E15: =8000000-700000-100000-1000000-1000000-1000000-4200000 -> 0 | F15: 45310 | G15: 26th | I15: 12 | J15: RAMONA GILBERT | K15: 22000000 | L15: =1000000+1000000+250000+2000000+1250000+1300000+2000000+1500000 -> 10300000 | M15: =K15-L15 -> 11700000 | N15: 45545 | O15: 17TH
A16: 13 | B16: RUQAIYA JAWAD | C16: 11000000 | D16: =C16-E16 -> 11000000 | E16: =10000000-1000000-1000000-1000000-1000000-1000000-1000000-1000000-3000000 -> 0 | F16: 45330 | G16: 15th | I16: 13 | J16: RUQAIYA JAWAD | K16: 24200000 | L16: =1862000+1862000+1862000+1862000+1862000+1862000 -> 11172000 | M16: =K16-L16 -> 13028000 | N16: 45587 | O16: 29TH
A17: 14 | B17: CATHERINE EDWARD | C17: 11000000 | D17: =C17-E17 -> 8568000 | E17: =10388000-612000-612000-612000-612000-612000-612000-612000-612000-612000-612000-612000-612000-612000 -> 2432000 | F17: 45341 | G17: 26th | I17: 14 | J17: CATHERINE EDWARD | M17: =K17-L17 -> 0
A18: 15 | B18: KEMMY MUGELE | C18: 11000000 | D18: =C18-E18 -> 7956000 | E18: =10388000-612000-612000-612000-612000-612000-612000-612000-612000-612000-612000-612000-612000 -> 3044000 | F18: 45357 | G18: 13th | I18: 15 | J18: KEMMY MUGELE | M18: =K18-L18 -> 0
A19: 16 | B19: REGINA DANIEL | C19: 11000000 | D19: =C19-E19 -> 7312000 | E19: =11000000-620000-600000-620000-612000-612000-612000-600000-612000-612000-600000-600000-612000 -> 3688000 | F19: 45391 | G19: 16th | I19: 16 | J19: REGINA DANIEL | M19: =K19-L19 -> 0
A20: 17 | B20: Upendo Mmary | C20: 11000000 | D20: =C20-E20 -> 3400000 | E20: =11000000-700000-700000-1000000-1000000 -> 7600000 | F20: 45402 | G20: 27th | I20: 17 | J20: Upendo Mmary | M20: =K20-L20 -> 0
A21: 18 | B21: Alma Mollel | C21: 11000000 | D21: =C21-E21 -> 11000000 | E21: =11000000-612000-612000-612000-612000-612000-612000-612000-1000000-2000000-3088000-620000-8000 -> 0 | F21: 45420 | G21: 15th | I21: 18 | J21: Alma Mollel | K21: 18150000 | L21: =1250000 -> 1250000 | M21: =K21-L21 -> 16900000 | N21: april
B22: TOTAL MONEY MOVES | C22: =SUM(C4:C21) -> 192500000 | D22: =SUM(D4:D20) -> 157272000 | E22: =SUM(E4:E19) -> 16628000 | J22: TOTAL MONEY MOVES | K22: =SUM(K4:K21) -> 205150000 | L22: =SUM(L4:L20) -> 52211000 | M22: =SUM(M4:M19) -> 134789000

Sheet CASHFLOW
B1: 45292 | C1: 45323 | D1: 45352 | E1: 45383 | F1: 45413 | G1: 45444 | H1: 45474 | I1: 45505 | J1: 45536 | K1: 45566 | L1: 45597 | M1: 45627
A2: OPENING BALANCE JANUARY 2023 AS PER BANK STATEMENT
A3: HISA ZA WANACHAMA | B3: =HISA!C23 -> 8800000 | C3: =HISA!D23 -> 8100000 | D3: =HISA!E23 -> 7300000 | E3: =HISA!F23 -> 5200000 | F3: =HISA!G23 -> 6000000 | G3: =HISA!H23 -> 3200000 | H3: =HISA!I23 -> 0 | I3: =HISA!J23 -> 0 | J3: =HISA!K23 -> 0
A4: MICHANGO MBALIMBALI | B4: =JAMII!C22 -> 270000 | C4: =JAMII!D22 -> 270000 | D4: =JAMII!E22 -> 255000 | E4: =JAMII!F22 -> 255000 | F4: =JAMII!G22 -> 225000 | G4: =JAMII!H22 -> 135000 | H4: =JAMII!I22 -> 0 | I4: =JAMII!J22 -> 0 | ... M4: =JAMII!N22 -> 0
A5: FAINI | B5: =FAINI!B21 -> 215000 | C5: =FAINI!C21 -> 352000 | D5: =FAINI!D21 -> 453000 | E5: =FAINI!E21 -> 411000 | F5: =FAINI!F21 -> 475000 | G5: =FAINI!G21 -> 0 | H5: =FAINI!H21 -> 0 | I5: =FAINI!I21 -> 0 | ... L5: =FAINI!L21 -> 0 | M5: =FAINI!N21 -> 0
A6: KIINGILIO | B6: 0 | C6: 0 | D6: 0 | E6: 0
A7: RIBA | B7: 6483000 | C7: 8181000 | D7: 7424000 | E7: 8937000 | F7: 10885000 | G7: 15132000 | H7: 14474000 | I7: 9912000
A8: JUMLA YA MAPATO | B8: =SUM(B3:B7) -> 15768000 | C8: =SUM(C3:C7) -> 16903000 | D8: =SUM(D3:D7) -> 15432000 | E8: =SUM(E3:E7) -> 14803000 | F8: =SUM(F3:F7) -> 17585000 | G8: =SUM(G3:G7) -> 18467000 | H8: =SUM(H3:H7) -> 14474000 | I8: =SUM(I3:I7) -> 9912000 | J8: =SUM(J3:J6) -> 0
A10: MATUMIZI
A11: MIKOPO KWENDA KWA WANACHAMA | B11: 10000000 | C11: 20000000 | D11: 10000000 | E11: 20000000 | F11: 15000000 | G11: 15000000 | H11: 20000000 | I11: 20000000 | J11: 20000000
A12: MATUMIZI YA KIJAMII | F12: 500000
A13: MATUMIZI YA WATIA SAINI | B13: 20000 | C13: 40000 | D13: 20000 | E13: 20000 | F13: 20000 | G13: 20000 | H13: 20000 | I13: 20000 | J13: 20000
A14: GHARAMA ZA KIBENKI
A15: JUMLA YA MATUMIZI | B15: =SUM(B11:B14) -> 10020000 | C15: =SUM(C11:C14) -> 20040000 | D15: =SUM(D11:D14) -> 10020000 | E15: =SUM(E11:E14) -> 20020000 | F15: =SUM(F11:F14) -> 15520000 | G15: =SUM(G11:G14) -> 15020000 | H15: =SUM(H11:H14) -> 20020000 | I15: =SUM(I11:I14) -> 20020000 | J15: =SUM(J11:J14) -> 20020000
A17: MAPATO-MATUMIZI(KIASI BAKI) | B17: =B8-B15 -> 5748000 | C17: =C8-C15 -> -3137000 | D17: =D8-D15 -> 5412000 | E17: =E8-E15 -> -5217000 | F17: =F8-F15 -> 2065000 | G17: =G8-G15 -> 3447000 | H17: =H8-H15 -> -5546000 | I17: =I8-I15 -> -10108000
A19: BANK-OPENING BALANCE 2024 | D19: 3330787.1
A20: JUMLA YA MAPATO | D20: =D19+B8+C8+D8+E8+F8+G8+H8+I8 -> 1.2667479e+08
A21: JUMLA YA MATUMIZI | D21: =B15+C15+D15+E15+F15+G15+H15+I15 -> 130680000
A22: KIASI KILICHOBAKI | D22: =D20-D21 -> -4005212.9 | E22: =B17+C17+D17+E17+F17+G17+H17+I17 -> -7336000 | F22: =D22-E22 -> 3330787.1 | G22: opening balance
C23: Bank-NOW | E23: 45579
C24: Unseen | E24: unpaid fain-163,000 | F24: Cath-200k topup
E25: 825000 | F25: ipo kwenye acc mm sina@@@@@
